Workbook

Sheet BEHAVIOURABILITY
B1: Decision Making | C1: Self-Management | D1: Communication | E1: Engagement
A2: TASK T1 <Riconoscimento dei segnali di stress e stanchezza> | B2: K&S | D2: SE | E2: MOT
A3: TASK T2 <Gestione della transizione> | B3: PC | C3: PC | E3: MOT
A4: TASK T3 <Scelta del momento per una pausa> | B4: K&S, SE | C4: PC | E4: MOT
A5: TASK T4 <Esecuzione di esercizi> | C5: K&S | E5: MOT
A6: TASK T5 <Monitoraggio dei parametri personali> | B6: K&S | D6: SE
A7: TASK T6 <Regolazione della postura durante la giornata> | C7: PC | D7: K&S | E7: MOT
A8: TASK T7 <Pianificazione del benessere quotidiano> | B8: SE | C8: PC | E8: MOT
A16: Legenda
A17: SE = Self-Efficacy
A18: K&S = Knowledge & Skills
A19: PC = Personal Control
A20: MOT = Motivation

Sheet Quest.Utente1
B1: Self Efficacy | C1: Scarso | D1: Sufficiente | E1: Buono | F1: Molto Buono | G1: Eccellente | H1: Valore | I1: Segnare la risposta con una X maiuscola
A2: T1_SE1 | B2: Quanto ti senti sicuro/a di saper distinguere un semplice affaticamento da un segnale di stress acuto? | C2: X | H2: =IF(C2="X",1)+IF(D2="X",2)+IF(E2="X",3)+IF(F2="X",4)+IF(G2="X",5) -> 1
A3: T1_SE2 | B3: Quanto sei convinto/a di poter identificare correttamente i segnali di tensione muscolare prima che diventino dolore? | D3: X | H3: =IF(C3="X",1)+IF(D3="X",2)+IF(E3="X",3)+IF(F3="X",4)+IF(G3="X",5) -> 2
B4: Knowledge&Skills
A5: T1_KS1 | B5: Quanto pensi di conoscere i segnali biometrici (battito, tensione) che il tuo corpo invia quando è sotto sforzo? | E5: X | H5: =IF(C5="X",1)+IF(D5="X",2)+IF(E5="X",3)+IF(F5="X",4)+IF(G5="X",5) -> 3
A6: T1_KS2 | B6: Quanto sei esperto/a nel collegare un sintomo fisico (es. mal di testa) a una causa specifica della tua giornata? | D6: X | H6: =IF(C6="X",1)+IF(D6="X",2)+IF(E6="X",3)+IF(F6="X",4)+IF(G6="X",5) -> 2
B7: Motivation
A8: T1_MOT1 | B8: Quanto sei motivato/a a fermarti immediatamente quando avverti un segnale di malessere fisico? | C8: X | H8: =IF(C8="X",1)+IF(D8="X",2)+IF(E8="X",3)+IF(F8="X",4)+IF(G8="X",5) -> 1
A9: … | B9: Personal Control
A10: T2_PC1 | B10: Quanto senti di avere il potere di decidere di fermarti tra un meeting e l'altro? | D10: X | H10: =IF(C10="X",1)+IF(D10="X",2)+IF(E10="X",3)+IF(F10="X",4)+IF(G10="X",5) -> 2
A11: T2_PC2 | B11: Quanto pensi che la qualità del tuo prossimo impegno dipenda dalla tua capacità di resettare la mente ora? | F11: X | H11: =IF(C11="X",1)+IF(D11="X",2)+IF(E11="X",3)+IF(F11="X",4)+IF(G11="X",5) -> 4
B12: Motivation
A13: T2_MOT1 | B13: Quanto impegno metti nel cercare attivamente un momento di stacco in un'agenda molto fitta? | C13: X | H13: =IF(C13="X",1)+IF(D13="X",2)+IF(E13="X",3)+IF(F13="X",4)+IF(G13="X",5) -> 1
A14: … | B14: Self Efficacy
A15: T3_SE1 | B15: Quanto sei sicuro/a di riuscire a trovare il momento giusto in agenda senza che questo influisca sui tuoi task? | E15: X | H15: =IF(C15="X",1)+IF(D15="X",2)+IF(E15="X",3)+IF(F15="X",4)+IF(G15="X",5) -> 3
A16: T3_SE2 | B16: Quanto ti senti capace di ignorare le pressioni esterne per prenderti un momento di pausa necessario? | C16: X | H16: =IF(C16="X",1)+IF(D16="X",2)+IF(E16="X",3)+IF(F16="X",4)+IF(G16="X",5) -> 1
B17: Knowledge&Skills
A18: T3_KS1 | B18: Quanto sai valutare correttamente se la tua riserva di energia mentale è effettivamente esaurita? | F18: X | H18: =IF(C18="X",1)+IF(D18="X",2)+IF(E18="X",3)+IF(F18="X",4)+IF(G18="X",5) -> 4
A19: T3_KS2 | B19: Quanto conosci le tecniche per incastrare micro-momenti di benessere nella tua routine digitale? | D19: X | H19: =IF(C19="X",1)+IF(D19="X",2)+IF(E19="X",3)+IF(F19="X",4)+IF(G19="X",5) -> 2
B20: Personal Control
A21: T3_PC1 | B21: Quanto ti senti libero/a di gestire il tuo tempo senza sentirti in colpa verso colleghi o clienti? | G21: X | H21: =IF(C21="X",1)+IF(D21="X",2)+IF(E21="X",3)+IF(F21="X",4)+IF(G21="X",5) -> 5
A22: T3_PC2 | B22: Quanto senti di poter modificare i tuoi piani se il tuo corpo ti segnala una necessità improvvisa? | E22: X | H22: =IF(C22="X",1)+IF(D22="X",2)+IF(E22="X",3)+IF(F22="X",4)+IF(G22="X",5) -> 3
B23: Motivation
A24: T3_MOT1 | B24: Quanto è importante per te non arrivare a fine giornata completamente esausto/a? | F24: X | H24: =IF(C24="X",1)+IF(D24="X",2)+IF(E24="X",3)+IF(F24="X",4)+IF(G24="X",5) -> 4
A25: … | B25: Knowledge&Skills
A26: T4_KS1 | B26: Quanto conosci correttamente le tecniche di respirazione o gli esercizi suggeriti dalle varie app? | C26: X | H26: =IF(C26="X",1)+IF(D26="X",2)+IF(E26="X",3)+IF(F26="X",4)+IF(G26="X",5) -> 1
A27: T4_KS2 | B27: Quanto ti senti preparato/a a eseguire esercizi anche in un ambiente non sportivo (ufficio)? | D27: X | H27: =IF(C27="X",1)+IF(D27="X",2)+IF(E27="X",3)+IF(F27="X",4)+IF(G27="X",5) -> 2
B28: Motivation
A29: T4_MOT1 | B29: Quanto sei costante nel portare a termine un'esercizio una volta che hai deciso di iniziarlo? | E29: X | H29: =IF(C29="X",1)+IF(D29="X",2)+IF(E29="X",3)+IF(F29="X",4)+IF(G29="X",5) -> 3
A30: … | B30: Self Efficacy
A31: T5_SE1 | B31: In che misura ti senti capace di migliorare i tuoi livelli di stress e recupero agendo sulle tue abitudini? | G31: X | H31: =IF(C31="X",1)+IF(D31="X",2)+IF(E31="X",3)+IF(F31="X",4)+IF(G31="X",5) -> 5
A32: T5_SE2 | B32: Quanto ti fidi della tua capacità di interpretare correttamente i dati che le varie app ti dicono? | D32: X | H32: =IF(C32="X",1)+IF(D32="X",2)+IF(E32="X",3)+IF(F32="X",4)+IF(G32="X",5) -> 2
B33: Knowledge&Skills
A34: T5_KS1 | B34: Quanto comprendi il significato di termini come HRV (variabilità cardiaca) o stress del sistema nervoso? | E34: X | H34: =IF(C34="X",1)+IF(D34="X",2)+IF(E34="X",3)+IF(F34="X",4)+IF(G34="X",5) -> 3
A35: T5_KS2 | B35: Quanto sai tradurre un grafico o un dato dell'app in un'azione pratica per il tuo benessere? | E35: X | H35: =IF(C35="X",1)+IF(D35="X",2)+IF(E35="X",3)+IF(F35="X",4)+IF(G35="X",5) -> 3
A36: … | B36: Personal Control
A37: T6_PC1 | B37: Quanto ti senti in grado di mantenere l'attenzione sulla tua postura mentre sei concentrato/a al 100% sul lavoro? | D37: X | H37: =IF(C37="X",1)+IF(D37="X",2)+IF(E37="X",3)+IF(F37="X",4)+IF(G37="X",5) -> 2
A38: T6_PC2 | B38: Quanto senti di avere il controllo sui tuoi movimenti involontari (es. incurvare le spalle)? | D38: X | H38: =IF(C38="X",1)+IF(D38="X",2)+IF(E38="X",3)+IF(F38="X",4)+IF(G38="X",5) -> 2
B39: Knowledge&Skills
A40: T6_KS1 | B40: Quanto conosci la posizione ergonomica corretta che dovresti tenere alla tua scrivania? | F40: X | H40: =IF(C40="X",1)+IF(D40="X",2)+IF(E40="X",3)+IF(F40="X",4)+IF(G40="X",5) -> 4
...

Sheet Quest.Utente2
B1: Self Efficacy | C1: Scarso | D1: Sufficiente | E1: Buono | F1: Molto Buono | G1: Eccellente | H1: Valore | I1: Segnare la risposta con una X maiuscola
A2: T1_SE1 | B2: Quanto ti senti sicuro/a di saper distinguere un semplice affaticamento da un segnale di stress acuto? | D2: X | H2: =IF(C2="X",1)+IF(D2="X",2)+IF(E2="X",3)+IF(F2="X",4)+IF(G2="X",5) -> 2
A3: T1_SE2 | B3: Quanto sei convinto/a di poter identificare correttamente i segnali di tensione muscolare prima che diventino dolore? | D3: X | H3: =IF(C3="X",1)+IF(D3="X",2)+IF(E3="X",3)+IF(F3="X",4)+IF(G3="X",5) -> 2
B4: Knowledge&Skills
A5: T1_KS1 | B5: Quanto pensi di conoscere i segnali biometrici (battito, tensione) che il tuo corpo invia quando è sotto sforzo? | C5: X | H5: =IF(C5="X",1)+IF(D5="X",2)+IF(E5="X",3)+IF(F5="X",4)+IF(G5="X",5) -> 1
A6: T1_KS2 | B6: Quanto sei esperto/a nel collegare un sintomo fisico (es. mal di testa) a una causa specifica della tua giornata? | C6: X | H6: =IF(C6="X",1)+IF(D6="X",2)+IF(E6="X",3)+IF(F6="X",4)+IF(G6="X",5) -> 1
B7: Motivation
A8: T1_MOT1 | B8: Quanto sei motivato/a a fermarti immediatamente quando avverti un segnale di malessere fisico? | E8: X | H8: =IF(C8="X",1)+IF(D8="X",2)+IF(E8="X",3)+IF(F8="X",4)+IF(G8="X",5) -> 3
A9: … | B9: Personal Control
A10: T2_PC1 | B10: Quanto senti di avere il potere di decidere di fermarti tra un meeting e l'altro? | E10: X | H10: =IF(C10="X",1)+IF(D10="X",2)+IF(E10="X",3)+IF(F10="X",4)+IF(G10="X",5) -> 3
A11: T2_PC2 | B11: Quanto pensi che la qualità del tuo prossimo impegno dipenda dalla tua capacità di resettare la mente ora? | G11: X | H11: =IF(C11="X",1)+IF(D11="X",2)+IF(E11="X",3)+IF(F11="X",4)+IF(G11="X",5) -> 5
B12: Motivation
A13: T2_MOT1 | B13: Quanto impegno metti nel cercare attivamente un momento di stacco in un'agenda molto fitta? | F13: X | H13: =IF(C13="X",1)+IF(D13="X",2)+IF(E13="X",3)+IF(F13="X",4)+IF(G13="X",5) -> 4
A14: … | B14: Self Efficacy
A15: T3_SE1 | B15: Quanto sei sicuro/a di riuscire a trovare il momento giusto in agenda senza che questo influisca sui tuoi task? | E15: X | H15: =IF(C15="X",1)+IF(D15="X",2)+IF(E15="X",3)+IF(F15="X",4)+IF(G15="X",5) -> 3
A16: T3_SE2 | B16: Quanto ti senti capace di ignorare le pressioni esterne per prenderti un momento di pausa necessario? | E16: X | H16: =IF(C16="X",1)+IF(D16="X",2)+IF(E16="X",3)+IF(F16="X",4)+IF(G16="X",5) -> 3
B17: Knowledge&Skills
A18: T3_KS1 | B18: Quanto sai valutare correttamente se la tua riserva di energia mentale è effettivamente esaurita? | F18: X | H18: =IF(C18="X",1)+IF(D18="X",2)+IF(E18="X",3)+IF(F18="X",4)+IF(G18="X",5) -> 4
A19: T3_KS2 | B19: Quanto conosci le tecniche per incastrare micro-momenti di benessere nella tua routine digitale? | C19: X | H19: =IF(C19="X",1)+IF(D19="X",2)+IF(E19="X",3)+IF(F19="X",4)+IF(G19="X",5) -> 1
B20: Personal Control
A21: T3_PC1 | B21: Quanto ti senti libero/a di gestire il tuo tempo senza sentirti in colpa verso colleghi o clienti? | G21: X | H21: =IF(C21="X",1)+IF(D21="X",2)+IF(E21="X",3)+IF(F21="X",4)+IF(G21="X",5) -> 5
A22: T3_PC2 | B22: Quanto senti di poter modificare i tuoi piani se il tuo corpo ti segnala una necessità improvvisa? | E22: X | H22: =IF(C22="X",1)+IF(D22="X",2)+IF(E22="X",3)+IF(F22="X",4)+IF(G22="X",5) -> 3
B23: Motivation
A24: T3_MOT1 | B24: Quanto è importante per te non arrivare a fine giornata completamente esausto/a? | G24: X | H24: =IF(C24="X",1)+IF(D24="X",2)+IF(E24="X",3)+IF(F24="X",4)+IF(G24="X",5) -> 5
A25: … | B25: Knowledge&Skills
A26: T4_KS1 | B26: Quanto conosci correttamente le tecniche di respirazione o gli esercizi suggeriti dalle varie app? | E26: X | H26: =IF(C26="X",1)+IF(D26="X",2)+IF(E26="X",3)+IF(F26="X",4)+IF(G26="X",5) -> 3
A27: T4_KS2 | B27: Quanto ti senti preparato/a a eseguire esercizi anche in un ambiente non sportivo (ufficio)? | C27: X | H27: =IF(C27="X",1)+IF(D27="X",2)+IF(E27="X",3)+IF(F27="X",4)+IF(G27="X",5) -> 1
B28: Motivation
A29: T4_MOT1 | B29: Quanto sei costante nel portare a termine un'esercizio una volta che hai deciso di iniziarlo? | D29: X | H29: =IF(C29="X",1)+IF(D29="X",2)+IF(E29="X",3)+IF(F29="X",4)+IF(G29="X",5) -> 2
A30: … | B30: Self Efficacy
A31: T5_SE1 | B31: In che misura ti senti capace di migliorare i tuoi livelli di stress e recupero agendo sulle tue abitudini? | E31: X | H31: =IF(C31="X",1)+IF(D31="X",2)+IF(E31="X",3)+IF(F31="X",4)+IF(G31="X",5) -> 3
A32: T5_SE2 | B32: Quanto ti fidi della tua capacità di interpretare correttamente i dati che le varie app ti dicono? | F32: X | H32: =IF(C32="X",1)+IF(D32="X",2)+IF(E32="X",3)+IF(F32="X",4)+IF(G32="X",5) -> 4
B33: Knowledge&Skills
A34: T5_KS1 | B34: Quanto comprendi il significato di termini come HRV (variabilità cardiaca) o stress del sistema nervoso? | C34: X | H34: =IF(C34="X",1)+IF(D34="X",2)+IF(E34="X",3)+IF(F34="X",4)+IF(G34="X",5) -> 1
A35: T5_KS2 | B35: Quanto sai tradurre un grafico o un dato dell'app in un'azione pratica per il tuo benessere? | D35: X | H35: =IF(C35="X",1)+IF(D35="X",2)+IF(E35="X",3)+IF(F35="X",4)+IF(G35="X",5) -> 2
A36: … | B36: Personal Control
A37: T6_PC1 | B37: Quanto ti senti in grado di mantenere l'attenzione sulla tua postura mentre sei concentrato/a al 100% sul lavoro? | C37: X | H37: =IF(C37="X",1)+IF(D37="X",2)+IF(E37="X",3)+IF(F37="X",4)+IF(G37="X",5) -> 1
A38: T6_PC2 | B38: Quanto senti di avere il controllo sui tuoi movimenti involontari (es. incurvare le spalle)? | C38: X | H38: =IF(C38="X",1)+IF(D38="X",2)+IF(E38="X",3)+IF(F38="X",4)+IF(G38="X",5) -> 1
B39: Knowledge&Skills
A40: T6_KS1 | B40: Quanto conosci la posizione ergonomica corretta che dovresti tenere alla tua scrivania? | G40: X | H40: =IF(C40="X",1)+IF(D40="X",2)+IF(E40="X",3)+IF(F40="X",4)+IF(G40="X",5) -> 5
...

Sheet Quest.Utente3
B1: Self Efficacy | C1: Scarso | D1: Sufficiente | E1: Buono | F1: Molto Buono | G1: Eccellente | H1: Valore | I1: Segnare la risposta con una X maiuscola
A2: T1_SE1 | B2: Quanto ti senti sicuro/a di saper distinguere un semplice affaticamento da un segnale di stress acuto? | G2: X | H2: =IF(C2="X",1)+IF(D2="X",2)+IF(E2="X",3)+IF(F2="X",4)+IF(G2="X",5) -> 5
A3: T1_SE2 | B3: Quanto sei convinto/a di poter identificare correttamente i segnali di tensione muscolare prima che diventino dolore? | F3: X | H3: =IF(C3="X",1)+IF(D3="X",2)+IF(E3="X",3)+IF(F3="X",4)+IF(G3="X",5) -> 4
B4: Knowledge&Skills
A5: T1_KS1 | B5: Quanto pensi di conoscere i segnali biometrici (battito, tensione) che il tuo corpo invia quando è sotto sforzo? | F5: X | H5: =IF(C5="X",1)+IF(D5="X",2)+IF(E5="X",3)+IF(F5="X",4)+IF(G5="X",5) -> 4
A6: T1_KS2 | B6: Quanto sei esperto/a nel collegare un sintomo fisico (es. mal di testa) a una causa specifica della tua giornata? | G6: X | H6: =IF(C6="X",1)+IF(D6="X",2)+IF(E6="X",3)+IF(F6="X",4)+IF(G6="X",5) -> 5
B7: Motivation
A8: T1_MOT1 | B8: Quanto sei motivato/a a fermarti immediatamente quando avverti un segnale di malessere fisico? | G8: X | H8: =IF(C8="X",1)+IF(D8="X",2)+IF(E8="X",3)+IF(F8="X",4)+IF(G8="X",5) -> 5
A9: … | B9: Personal Control
A10: T2_PC1 | B10: Quanto senti di avere il potere di decidere di fermarti tra un meeting e l'altro? | E10: X | H10: =IF(C10="X",1)+IF(D10="X",2)+IF(E10="X",3)+IF(F10="X",4)+IF(G10="X",5) -> 3
A11: T2_PC2 | B11: Quanto pensi che la qualità del tuo prossimo impegno dipenda dalla tua capacità di resettare la mente ora? | F11: X | H11: =IF(C11="X",1)+IF(D11="X",2)+IF(E11="X",3)+IF(F11="X",4)+IF(G11="X",5) -> 4
B12: Motivation
A13: T2_MOT1 | B13: Quanto impegno metti nel cercare attivamente un momento di stacco in un'agenda molto fitta? | F13: X | H13: =IF(C13="X",1)+IF(D13="X",2)+IF(E13="X",3)+IF(F13="X",4)+IF(G13="X",5) -> 4
A14: … | B14: Self Efficacy
A15: T3_SE1 | B15: Quanto sei sicuro/a di riuscire a trovare il momento giusto in agenda senza che questo influisca sui tuoi task? | F15: X | H15: =IF(C15="X",1)+IF(D15="X",2)+IF(E15="X",3)+IF(F15="X",4)+IF(G15="X",5) -> 4
A16: T3_SE2 | B16: Quanto ti senti capace di ignorare le pressioni esterne per prenderti un momento di pausa necessario? | F16: X | H16: =IF(C16="X",1)+IF(D16="X",2)+IF(E16="X",3)+IF(F16="X",4)+IF(G16="X",5) -> 4
B17: Knowledge&Skills
A18: T3_KS1 | B18: Quanto sai valutare correttamente se la tua riserva di energia mentale è effettivamente esaurita? | E18: X | H18: =IF(C18="X",1)+IF(D18="X",2)+IF(E18="X",3)+IF(F18="X",4)+IF(G18="X",5) -> 3
A19: T3_KS2 | B19: Quanto conosci le tecniche per incastrare micro-momenti di benessere nella tua routine digitale? | D19: X | H19: =IF(C19="X",1)+IF(D19="X",2)+IF(E19="X",3)+IF(F19="X",4)+IF(G19="X",5) -> 2
B20: Personal Control
A21: T3_PC1 | B21: Quanto ti senti libero/a di gestire il tuo tempo senza sentirti in colpa verso colleghi o clienti? | F21: X | H21: =IF(C21="X",1)+IF(D21="X",2)+IF(E21="X",3)+IF(F21="X",4)+IF(G21="X",5) -> 4
A22: T3_PC2 | B22: Quanto senti di poter modificare i tuoi piani se il tuo corpo ti segnala una necessità improvvisa? | F22: X | H22: =IF(C22="X",1)+IF(D22="X",2)+IF(E22="X",3)+IF(F22="X",4)+IF(G22="X",5) -> 4
B23: Motivation
A24: T3_MOT1 | B24: Quanto è importante per te non arrivare a fine giornata completamente esausto/a? | G24: X | H24: =IF(C24="X",1)+IF(D24="X",2)+IF(E24="X",3)+IF(F24="X",4)+IF(G24="X",5) -> 5
A25: … | B25: Knowledge&Skills
A26: T4_KS1 | B26: Quanto conosci correttamente le tecniche di respirazione o gli esercizi suggeriti dalle varie app? | C26: X | H26: =IF(C26="X",1)+IF(D26="X",2)+IF(E26="X",3)+IF(F26="X",4)+IF(G26="X",5) -> 1
A27: T4_KS2 | B27: Quanto ti senti preparato/a a eseguire esercizi anche in un ambiente non sportivo (ufficio)? | C27: X | H27: =IF(C27="X",1)+IF(D27="X",2)+IF(E27="X",3)+IF(F27="X",4)+IF(G27="X",5) -> 1
B28: Motivation
A29: T4_MOT1 | B29: Quanto sei costante nel portare a termine un'esercizio una volta che hai deciso di iniziarlo? | D29: X | H29: =IF(C29="X",1)+IF(D29="X",2)+IF(E29="X",3)+IF(F29="X",4)+IF(G29="X",5) -> 2
A30: … | B30: Self Efficacy
A31: T5_SE1 | B31: In che misura ti senti capace di migliorare i tuoi livelli di stress e recupero agendo sulle tue abitudini? | E31: X | H31: =IF(C31="X",1)+IF(D31="X",2)+IF(E31="X",3)+IF(F31="X",4)+IF(G31="X",5) -> 3
A32: T5_SE2 | B32: Quanto ti fidi della tua capacità di interpretare correttamente i dati che le varie app ti dicono? | D32: X | H32: =IF(C32="X",1)+IF(D32="X",2)+IF(E32="X",3)+IF(F32="X",4)+IF(G32="X",5) -> 2
B33: Knowledge&Skills
A34: T5_KS1 | B34: Quanto comprendi il significato di termini come HRV (variabilità cardiaca) o stress del sistema nervoso? | C34: X | H34: =IF(C34="X",1)+IF(D34="X",2)+IF(E34="X",3)+IF(F34="X",4)+IF(G34="X",5) -> 1
A35: T5_KS2 | B35: Quanto sai tradurre un grafico o un dato dell'app in un'azione pratica per il tuo benessere? | C35: X | H35: =IF(C35="X",1)+IF(D35="X",2)+IF(E35="X",3)+IF(F35="X",4)+IF(G35="X",5) -> 1
A36: … | B36: Personal Control
A37: T6_PC1 | B37: Quanto ti senti in grado di mantenere l'attenzione sulla tua postura mentre sei concentrato/a al 100% sul lavoro? | E37: X | H37: =IF(C37="X",1)+IF(D37="X",2)+IF(E37="X",3)+IF(F37="X",4)+IF(G37="X",5) -> 3
A38: T6_PC2 | B38: Quanto senti di avere il controllo sui tuoi movimenti involontari (es. incurvare le spalle)? | D38: X | H38: =IF(C38="X",1)+IF(D38="X",2)+IF(E38="X",3)+IF(F38="X",4)+IF(G38="X",5) -> 2
B39: Knowledge&Skills
A40: T6_KS1 | B40: Quanto conosci la posizione ergonomica corretta che dovresti tenere alla tua scrivania? | E40: X | H40: =IF(C40="X",1)+IF(D40="X",2)+IF(E40="X",3)+IF(F40="X",4)+IF(G40="X",5) -> 3
...

Sheet Quest.Utente4
B1: Self Efficacy | C1: Scarso | D1: Sufficiente | E1: Buono | F1: Molto Buono | G1: Eccellente | H1: Valore | I1: Segnare la risposta con una X maiuscola
A2: T1_SE1 | B2: Quanto ti senti sicuro/a di saper distinguere un semplice affaticamento da un segnale di stress acuto? | D2: X | H2: =IF(C2="X",1)+IF(D2="X",2)+IF(E2="X",3)+IF(F2="X",4)+IF(G2="X",5) -> 2
A3: T1_SE2 | B3: Quanto sei convinto/a di poter identificare correttamente i segnali di tensione muscolare prima che diventino dolore? | C3: X | H3: =IF(C3="X",1)+IF(D3="X",2)+IF(E3="X",3)+IF(F3="X",4)+IF(G3="X",5) -> 1
B4: Knowledge&Skills
A5: T1_KS1 | B5: Quanto pensi di conoscere i segnali biometrici (battito, tensione) che il tuo corpo invia quando è sotto sforzo? | D5: X | H5: =IF(C5="X",1)+IF(D5="X",2)+IF(E5="X",3)+IF(F5="X",4)+IF(G5="X",5) -> 2
A6: T1_KS2 | B6: Quanto sei esperto/a nel collegare un sintomo fisico (es. mal di testa) a una causa specifica della tua giornata? | E6: X | H6: =IF(C6="X",1)+IF(D6="X",2)+IF(E6="X",3)+IF(F6="X",4)+IF(G6="X",5) -> 3
B7: Motivation
A8: T1_MOT1 | B8: Quanto sei motivato/a a fermarti immediatamente quando avverti un segnale di malessere fisico? | F8: X | H8: =IF(C8="X",1)+IF(D8="X",2)+IF(E8="X",3)+IF(F8="X",4)+IF(G8="X",5) -> 4
A9: … | B9: Personal Control
A10: T2_PC1 | B10: Quanto senti di avere il potere di decidere di fermarti tra un meeting e l'altro? | E10: X | H10: =IF(C10="X",1)+IF(D10="X",2)+IF(E10="X",3)+IF(F10="X",4)+IF(G10="X",5) -> 3
A11: T2_PC2 | B11: Quanto pensi che la qualità del tuo prossimo impegno dipenda dalla tua capacità di resettare la mente ora? | E11: X | H11: =IF(C11="X",1)+IF(D11="X",2)+IF(E11="X",3)+IF(F11="X",4)+IF(G11="X",5) -> 3
B12: Motivation
A13: T2_MOT1 | B13: Quanto impegno metti nel cercare attivamente un momento di stacco in un'agenda molto fitta? | C13: X | H13: =IF(C13="X",1)+IF(D13="X",2)+IF(E13="X",3)+IF(F13="X",4)+IF(G13="X",5) -> 1
A14: … | B14: Self Efficacy
A15: T3_SE1 | B15: Quanto sei sicuro/a di riuscire a trovare il momento giusto in agenda senza che questo influisca sui tuoi task? | E15: X | H15: =IF(C15="X",1)+IF(D15="X",2)+IF(E15="X",3)+IF(F15="X",4)+IF(G15="X",5) -> 3
A16: T3_SE2 | B16: Quanto ti senti capace di ignorare le pressioni esterne per prenderti un momento di pausa necessario? | C16: X | H16: =IF(C16="X",1)+IF(D16="X",2)+IF(E16="X",3)+IF(F16="X",4)+IF(G16="X",5) -> 1
B17: Knowledge&Skills
A18: T3_KS1 | B18: Quanto sai valutare correttamente se la tua riserva di energia mentale è effettivamente esaurita? | C18: X | H18: =IF(C18="X",1)+IF(D18="X",2)+IF(E18="X",3)+IF(F18="X",4)+IF(G18="X",5) -> 1
A19: T3_KS2 | B19: Quanto conosci le tecniche per incastrare micro-momenti di benessere nella tua routine digitale? | C19: X | H19: =IF(C19="X",1)+IF(D19="X",2)+IF(E19="X",3)+IF(F19="X",4)+IF(G19="X",5) -> 1
B20: Personal Control
A21: T3_PC1 | B21: Quanto ti senti libero/a di gestire il tuo tempo senza sentirti in colpa verso colleghi o clienti? | F21: X | H21: =IF(C21="X",1)+IF(D21="X",2)+IF(E21="X",3)+IF(F21="X",4)+IF(G21="X",5) -> 4
A22: T3_PC2 | B22: Quanto senti di poter modificare i tuoi piani se il tuo corpo ti segnala una necessità improvvisa? | D22: X | H22: =IF(C22="X",1)+IF(D22="X",2)+IF(E22="X",3)+IF(F22="X",4)+IF(G22="X",5) -> 2
B23: Motivation
A24: T3_MOT1 | B24: Quanto è importante per te non arrivare a fine giornata completamente esausto/a? | G24: X | H24: =IF(C24="X",1)+IF(D24="X",2)+IF(E24="X",3)+IF(F24="X",4)+IF(G24="X",5) -> 5
A25: … | B25: Knowledge&Skills
A26: T4_KS1 | B26: Quanto conosci correttamente le tecniche di respirazione o gli esercizi suggeriti dalle varie app? | D26: X | H26: =IF(C26="X",1)+IF(D26="X",2)+IF(E26="X",3)+IF(F26="X",4)+IF(G26="X",5) -> 2
A27: T4_KS2 | B27: Quanto ti senti preparato/a a eseguire esercizi anche in un ambiente non sportivo (ufficio)? | E27: X | H27: =IF(C27="X",1)+IF(D27="X",2)+IF(E27="X",3)+IF(F27="X",4)+IF(G27="X",5) -> 3
B28: Motivation
A29: T4_MOT1 | B29: Quanto sei costante nel portare a termine un'esercizio una volta che hai deciso di iniziarlo? | E29: X | H29: =IF(C29="X",1)+IF(D29="X",2)+IF(E29="X",3)+IF(F29="X",4)+IF(G29="X",5) -> 3
A30: … | B30: Self Efficacy
A31: T5_SE1 | B31: In che misura ti senti capace di migliorare i tuoi livelli di stress e recupero agendo sulle tue abitudini? | F31: X | H31: =IF(C31="X",1)+IF(D31="X",2)+IF(E31="X",3)+IF(F31="X",4)+IF(G31="X",5) -> 4
A32: T5_SE2 | B32: Quanto ti fidi della tua capacità di interpretare correttamente i dati che le varie app ti dicono? | D32: X | H32: =IF(C32="X",1)+IF(D32="X",2)+IF(E32="X",3)+IF(F32="X",4)+IF(G32="X",5) -> 2
B33: Knowledge&Skills
A34: T5_KS1 | B34: Quanto comprendi il significato di termini come HRV (variabilità cardiaca) o stress del sistema nervoso? | C34: X | H34: =IF(C34="X",1)+IF(D34="X",2)+IF(E34="X",3)+IF(F34="X",4)+IF(G34="X",5) -> 1
A35: T5_KS2 | B35: Quanto sai tradurre un grafico o un dato dell'app in un'azione pratica per il tuo benessere? | C35: X | H35: =IF(C35="X",1)+IF(D35="X",2)+IF(E35="X",3)+IF(F35="X",4)+IF(G35="X",5) -> 1
A36: … | B36: Personal Control
A37: T6_PC1 | B37: Quanto ti senti in grado di mantenere l'attenzione sulla tua postura mentre sei concentrato/a al 100% sul lavoro? | C37: X | H37: =IF(C37="X",1)+IF(D37="X",2)+IF(E37="X",3)+IF(F37="X",4)+IF(G37="X",5) -> 1
A38: T6_PC2 | B38: Quanto senti di avere il controllo sui tuoi movimenti involontari (es. incurvare le spalle)? | C38: X | H38: =IF(C38="X",1)+IF(D38="X",2)+IF(E38="X",3)+IF(F38="X",4)+IF(G38="X",5) -> 1
B39: Knowledge&Skills
A40: T6_KS1 | B40: Quanto conosci la posizione ergonomica corretta che dovresti tenere alla tua scrivania? | G40: X | H40: =IF(C40="X",1)+IF(D40="X",2)+IF(E40="X",3)+IF(F40="X",4)+IF(G40="X",5) -> 5
...

Sheet MEDIE
C1: Scarso | D1: Sufficiente | E1: Buono | F1: Molto Buono | G1: Eccellente | H1: Valore
A2: T1_SE1 | B2: Quanto ti senti sicuro/a di saper distinguere un semplice affaticamento da un segnale di stress acuto? | H2: =AVERAGE(Quest.Utente1!H2,Quest.Utente2!H2,Quest.Utente3!H2,Quest.Utente4!H2) -> 2.5
A3: T1_SE2 | B3: Quanto sei convinto/a di poter identificare correttamente i segnali di tensione muscolare prima che diventino dolore? | H3: =AVERAGE(Quest.Utente1!H3,Quest.Utente2!H3,Quest.Utente3!H3,Quest.Utente4!H3) -> 2.25
H4: =AVERAGE(H2:H3) -> 2.375
A5: T1_KS1 | B5: Quanto pensi di conoscere i segnali biometrici (battito, tensione) che il tuo corpo invia quando è sotto sforzo? | H5: =AVERAGE(Quest.Utente1!H5,Quest.Utente2!H5,Quest.Utente3!H5,Quest.Utente4!H5) -> 2.5
A6: T1_KS2 | B6: Quanto sei esperto/a nel collegare un sintomo fisico (es. mal di testa) a una causa specifica della tua giornata? | H6: =AVERAGE(Quest.Utente1!H6,Quest.Utente2!H6,Quest.Utente3!H6,Quest.Utente4!H6) -> 2.75
H7: =AVERAGE(H5:H6) -> 2.625
A8: T1_MOT1 | B8: Quanto sei motivato/a a fermarti immediatamente quando avverti un segnale di malessere fisico? | H8: =AVERAGE(Quest.Utente1!H8,Quest.Utente2!H8,Quest.Utente3!H8,Quest.Utente4!H8) -> 3.25
H9: =AVERAGE(H8) -> 3.25
A10: T2_PC1 | B10: Quanto senti di avere il potere di decidere di fermarti tra un meeting e l'altro? | H10: =AVERAGE(Quest.Utente1!H10,Quest.Utente2!H10,Quest.Utente3!H10,Quest.Utente4!H10) -> 2.75
A11: T2_PC2 | B11: Quanto pensi che la qualità del tuo prossimo impegno dipenda dalla tua capacità di resettare la mente ora? | H11: =AVERAGE(Quest.Utente1!H11,Quest.Utente2!H11,Quest.Utente3!H11,Quest.Utente4!H11) -> 4
H12: =AVERAGE(H10:H11) -> 3.375
A13: T2_MOT1 | B13: Quanto impegno metti nel cercare attivamente un momento di stacco in un'agenda molto fitta? | H13: =AVERAGE(Quest.Utente1!H13,Quest.Utente2!H13,Quest.Utente3!H13,Quest.Utente4!H13) -> 2.5
H14: =AVERAGE(H13) -> 2.5
A15: T3_SE1 | B15: Quanto sei sicuro/a di riuscire a trovare il momento giusto in agenda senza che questo influisca sui tuoi task? | H15: =AVERAGE(Quest.Utente1!H15,Quest.Utente2!H15,Quest.Utente3!H15,Quest.Utente4!H15) -> 3.25
A16: T3_SE2 | B16: Quanto ti senti capace di ignorare le pressioni esterne per prenderti un momento di pausa necessario? | H16: =AVERAGE(Quest.Utente1!H16,Quest.Utente2!H16,Quest.Utente3!H16,Quest.Utente4!H16) -> 2.25
H17: =AVERAGE(H15:H16) -> 2.75
A18: T3_KS1 | B18: Quanto ti senti capace di ignorare le pressioni esterne per prenderti un momento di pausa necessario? | H18: =AVERAGE(Quest.Utente1!H18,Quest.Utente2!H18,Quest.Utente3!H18,Quest.Utente4!H18) -> 3
A19: T3_KS2 | B19: Quanto conosci le tecniche per incastrare micro-momenti di benessere nella tua routine digitale? | H19: =AVERAGE(Quest.Utente1!H19,Quest.Utente2!H19,Quest.Utente3!H19,Quest.Utente4!H19) -> 1.5
H20: =AVERAGE(H18:H19) -> 2.25
A21: T3_PC1 | B21: Quanto ti senti libero/a di gestire il tuo tempo senza sentirti in colpa verso colleghi o clienti? | H21: =AVERAGE(Quest.Utente1!H21,Quest.Utente2!H21,Quest.Utente3!H21,Quest.Utente4!H21) -> 4.5
A22: T3_PC2 | B22: Quanto senti di poter modificare i tuoi piani se il tuo corpo ti segnala una necessità improvvisa? | H22: =AVERAGE(Quest.Utente1!H22,Quest.Utente2!H22,Quest.Utente3!H22,Quest.Utente4!H22) -> 3
H23: =AVERAGE(H21:H22) -> 3.75
A24: T3_MOT1 | B24: Quanto è importante per te non arrivare a fine giornata completamente esausto/a? | H24: =AVERAGE(Quest.Utente1!H24,Quest.Utente2!H24,Quest.Utente3!H24,Quest.Utente4!H24) -> 4.75
H25: =AVERAGE(H24) -> 4.75
A26: T4_KS1 | B26: Quanto conosci correttamente le tecniche di respirazione o gli esercizi suggeriti dalle varie app? | H26: =AVERAGE(Quest.Utente1!H26,Quest.Utente2!H26,Quest.Utente3!H26,Quest.Utente4!H26) -> 1.75
A27: T4_KS2 | B27: Quanto ti senti preparato/a a eseguire esercizi anche in un ambiente non sportivo (ufficio)? | H27: =AVERAGE(Quest.Utente1!H27,Quest.Utente2!H27,Quest.Utente3!H27,Quest.Utente4!H27) -> 1.75
H28: =AVERAGE(H26:H27) -> 1.75
A29: T4_MOT1 | B29: Quanto sei costante nel portare a termine un'esercizio una volta che hai deciso di iniziarlo? | H29: =AVERAGE(Quest.Utente1!H29,Quest.Utente2!H29,Quest.Utente3!H29,Quest.Utente4!H29) -> 2.5
H30: =AVERAGE(H29) -> 2.5
A31: T5_SE1 | B31: In che misura ti senti capace di migliorare i tuoi livelli di stress e recupero agendo sulle tue abitudini? | H31: =AVERAGE(Quest.Utente1!H31,Quest.Utente2!H31,Quest.Utente3!H31,Quest.Utente4!H31) -> 3.75
A32: T5_SE2 | B32: Quanto ti fidi della tua capacità di interpretare correttamente i dati che le varie app ti dicono? | H32: =AVERAGE(Quest.Utente1!H32,Quest.Utente2!H32,Quest.Utente3!H32,Quest.Utente4!H32) -> 2.5
H33: =AVERAGE(H31:H32) -> 3.125
A34: T5_KS1 | B34: Quanto comprendi il significato di termini come HRV (variabilità cardiaca) o stress del sistema nervoso? | H34: =AVERAGE(Quest.Utente1!H34,Quest.Utente2!H34,Quest.Utente3!H34,Quest.Utente4!H34) -> 1.5
A35: T5_KS2 | B35: Quanto sai tradurre un grafico o un dato dell'app in un'azione pratica per il tuo benessere? | H35: =AVERAGE(Quest.Utente1!H35,Quest.Utente2!H35,Quest.Utente3!H35,Quest.Utente4!H35) -> 1.75
H36: =AVERAGE(H34:H35) -> 1.625
A37: T6_PC1 | B37: Quanto ti senti in grado di mantenere l'attenzione sulla tua postura mentre sei concentrato/a al 100% sul lavoro? | H37: =AVERAGE(Quest.Utente1!H37,Quest.Utente2!H37,Quest.Utente3!H37,Quest.Utente4!H37) -> 1.75
A38: T6_PC2 | B38: Quanto senti di avere il controllo sui tuoi movimenti involontari (es. incurvare le spalle)? | H38: =AVERAGE(Quest.Utente1!H38,Quest.Utente2!H38,Quest.Utente3!H38,Quest.Utente4!H38) -> 1.5
H39: =AVERAGE(H37:H38) -> 1.625
A40: T6_KS1 | B40: Quanto conosci la posizione ergonomica corretta che dovresti tenere alla tua scrivania? | H40: =AVERAGE(Quest.Utente1!H40,Quest.Utente2!H40,Quest.Utente3!H40,Quest.Utente4!H40) -> 4.25
...

Sheet TabRisultati
A1: Task | B1: ISE | C1: IKS | D1: IPC | E1: IMOT
A2: T1 | B2: =MEDIE!H4 -> 2.375 | C2: =MEDIE!H7 -> 2.625 | E2: =MEDIE!H9 -> 3.25
A3: T2 | D3: =MEDIE!H12 -> 3.375 | E3: =MEDIE!H14 -> 2.5
A4: T3 | B4: =MEDIE!H17 -> 2.75 | C4: =MEDIE!H20 -> 2.25 | D4: =MEDIE!H23 -> 3.75 | E4: =MEDIE!H25 -> 4.75
A5: T4 | C5: =MEDIE!H28 -> 1.75 | E5: =MEDIE!H30 -> 2.5
A6: T5 | B6: =MEDIE!H33 -> 3.125 | C6: =MEDIE!H36 -> 1.625
A7: T6 | C7: =MEDIE!H42 -> 3.75 | D7: =MEDIE!H39 -> 1.625 | E7: =MEDIE!H44 -> 4.25
A8: T7 | B8: =MEDIE!H47 -> 3.75 | D8: =MEDIE!H50 -> 3.75 | E8: =MEDIE!H52 -> 5
A10: TOTAL | B10: =AVERAGE(B2:B8) -> 3 | C10: =AVERAGE(C2:C8) -> 2.4 | D10: =AVERAGE(D2:D8) -> 3.125 | E10: =AVERAGE(E2:E8) -> 3.7083333
